File: ex_py/python/55/1000-1.txt
Time(sec)	Force(kgf)	LGauge(mm)	Strain	Stress(MPa)	Stroke(mm)	TC3(C)	PTemp
0	-133.56	7.85E-05	1.76E-06	-16.665	0.15278	43.534	30.001
1	-132.37	-2.90E-05	1.15E-06	-16.519	0.15044	43.617	34.637
2	-132.11	-3.35E-05	5.70E-06	-16.499	0.15526	43.496	39.423
3	-132.01	-0.00038907	-2.39E-05	-16.494	0.15388	43.347	44.208
4	-141.42	0.0017725	0.00011955	-17.66	0.15335	43.711	48.994
5	-156.75	0.0041943	0.00028082	-19.577	0.15275	45.831	53.78
5.99999	-167.85	0.0081681	0.00054769	-20.969	0.15227	51.187	58.566
6.99999	-171.56	0.012929	0.00086968	-21.44	0.15274	59.233	63.351
7.99999	-172.76	0.016288	0.0010918	-21.596	0.15512	68.105	68.137
8.99999	-173.64	0.017085	0.0011437	-21.707	0.1534	76.356	72.923
9.99999	-170.37	0.015652	0.0010455	-21.303	0.15233	82.509	77.708
10.99999	-166.98	0.015225	0.0010166	-20.865	0.15451	86.175	82.494
11.99999	-168.82	0.015522	0.001034	-21.105	0.15421	88.797	87.28
12.99999	-176.5	0.01771	0.0011851	-22.084	0.15314	91.149	92.066
13.99999	-175.34	0.022322	0.00149	-21.918	0.15235	94.615	96.851
14.99999	-176.26	0.026915	0.0017907	-22.049	0.15544	99.665	101.64
15.9059	-177.09	0.029697	0.0019772	-22.146	0.15365	105.08	105.97
16.9059	-177.73	0.03216	0.0021422	-22.237	0.15397	111.17	110.76
17.9059	-178.12	0.033077	0.0022026	-22.304	0.15588	116.81	115.54
18.9059	-178.73	0.033676	0.0022404	-22.392	0.15471	121.79	120.33
19.9059	-178.65	0.035095	0.0023331	-22.36	0.15515	125.8	125.12
20.90589	-179.13	0.037816	0.0025119	-22.429	0.15458	129.68	129.9
21.90589	-179.65	0.040819	0.0027164	-22.492	0.15249	133.81	134.69
22.90589	-179.9	0.043466	0.0028934	-22.531	0.15399	138.65	139.47
23.90589	-179.88	0.046357	0.0030857	-22.53	0.153	143.58	144.26
24.90589	-180.25	0.049161	0.0032743	-22.571	0.15279	148.76	149.04
25.90589	-180.49	0.051215	0.0034118	-22.617	0.15414	154.15	153.83
26.90589	-180.37	0.052561	0.0035012	-22.6	0.15346	159.14	158.62
27.90589	-180.81	0.054266	0.0036144	-22.669	0.15375	163.69	163.4
28.90589	-180.79	0.05675	0.0037808	-22.657	0.1539	168.08	168.19
29.90589	-181.18	0.059475	0.0039654	-22.716	0.15152	172.61	172.97
30.90589	-181.41	0.062387	0.0041542	-22.742	0.15316	177.22	177.76
31.90588	-181.76	0.065271	0.0043428	-22.783	0.15273	182.02	182.54
32.90588	-181.58	0.067888	0.0045198	-22.765	0.15232	187.2	187.33
33.90588	-181.72	0.070174	0.0046722	-22.789	0.14953	192.29	192.12
34.90588	-181.71	0.072379	0.0048174	-22.803	0.15192	197.19	196.9
35.90588	-182.06	0.074662	0.0049708	-22.845	0.15029	201.96	201.69
36.90588	-182.38	0.077262	0.00514	-22.891	0.1491	206.39	206.47
37.90588	-182.31	0.079737	0.0052951	-22.901	0.15054	210.96	211.26
38.90588	-182.24	0.082572	0.0054859	-22.885	0.15091	215.86	216.04
39.90588	-182.22	0.08571	0.005696	-22.897	0.14969	220.54	220.83
40.90588	-182	0.088323	0.0058694	-22.865	0.15019	225.57	225.62
41.90587	-182.31	0.09074	0.0060251	-22.902	0.15011	230.26	230.4
42.90587	-182.38	0.09265	0.0061582	-22.921	0.14942	235.22	235.19
43.90587	-182.92	0.095683	0.0063564	-22.993	0.14823	240.05	239.97
44.90587	-182.95	0.098617	0.0065526	-22.997	0.14905	244.67	244.76
45.90587	-183.02	0.10069	0.0066937	-22.997	0.14993	249.39	249.54
46.90587	-183.1	0.1037	0.0068917	-23.005	0.1512	254.24	254.33
47.90587	-183.04	0.10616	0.0070561	-23.008	0.14952	259.1	259.12
48.90587	-182.86	0.10918	0.0072553	-22.987	0.14814	263.76	263.9
49.90587	-182.88	0.11202	0.0074457	-23.001	0.15031	268.57	268.69
50.90587	-183	0.11482	0.0076299	-23.022	0.15015	273.3	273.47
51.90587	-183.44	0.11753	0.0078105	-23.081	0.14923	278.09	278.26
52.90586	-183.63	0.12029	0.0079965	-23.102	0.14873	282.87	283.04
53.90586	-183.61	0.12295	0.0081662	-23.119	0.15186	287.94	287.83
54.90586	-183.36	0.12618	0.0083837	-23.094	0.1487	292.5	292.62
55.90586	-183.48	0.12837	0.0085251	-23.111	0.14812	297.38	297.4
56.8687	-183.36	0.13135	0.0087217	-23.099	0.14938	302.13	302.01
57.8687	-183.49	0.13427	0.0089144	-23.106	0.15058	306.74	306.79
58.8687	-183.53	0.1368	0.0090761	-23.135	0.14968	311.31	311.58
59.8687	-183.68	0.14014	0.0093039	-23.148	0.14712	316.16	316.37
60.8687	-183.54	0.14249	0.0094624	-23.136	0.14788	320.9	321.15
61.86869	-183.59	0.14476	0.0096079	-23.151	0.1475	325.98	325.94
62.86869	-183.59	0.14767	0.0097925	-23.153	0.1484	330.94	330.72
63.86869	-183.99	0.15081	0.01	-23.203	0.14782	335.54	335.51
64.86869	-184.26	0.15306	0.010153	-23.234	0.14771	340.54	340.29
65.86869	-184.27	0.15541	0.010307	-23.25	0.14654	345.19	345.08
66.86869	-184.09	0.15838	0.010504	-23.245	0.1452	349.65	349.87
67.86869	-184.41	0.16107	0.010682	-23.274	0.14743	354.35	354.65
68.86869	-184.04	0.16408	0.010878	-23.241	0.14606	358.85	359.44
69.86869	-184.18	0.16673	0.011056	-23.256	0.1498	363.91	364.22
70.86869	-184.48	0.17001	0.011273	-23.288	0.14658	368.59	369.01
71.86869	-184.69	0.17288	0.011457	-23.336	0.1503	373.62	373.79
72.86868	-184.82	0.17532	0.011615	-23.351	0.1481	378.64	378.58
73.86868	-184.87	0.17841	0.01183	-23.365	0.14871	383.58	383.37
74.86868	-184.73	0.18026	0.011952	-23.347	0.14929	388.36	388.15
75.86868	-184.55	0.18288	0.012119	-23.325	0.14904	393.23	392.94
76.86868	-185.04	0.18462	0.012239	-23.379	0.14693	397.78	397.72
77.86868	-185.31	0.18777	0.012441	-23.425	0.14715	402.38	402.51
78.86868	-185.32	0.1904	0.012614	-23.425	0.151	407.33	407.29
79.86868	-185.35	0.19303	0.012789	-23.446	0.14843	411.82	412.08
80.86868	-185.1	0.19573	0.012972	-23.428	0.14687	416.74	416.87
81.86868	-185.21	0.19858	0.013154	-23.432	0.14704	421.44	421.65
82.86867	-185.54	0.20053	0.013286	-23.472	0.14643	426.32	426.44
83.86867	-185.36	0.20298	0.013442	-23.448	0.15064	431.27	431.22
84.86867	-185.67	0.20609	0.013645	-23.493	0.15067	436.26	436.01
85.86867	-186.13	0.20795	0.013767	-23.567	0.149	440.84	440.8
86.86867	-186	0.21045	0.013934	-23.551	0.15085	445.44	445.58
87.86867	-186.02	0.21228	0.014047	-23.549	0.14956	449.98	450.37
88.86867	-185.69	0.21504	0.014236	-23.521	0.15094	454.92	455.15
89.86867	-186.08	0.21727	0.014377	-23.575	0.14787	459.44	459.94
90.86867	-186.02	0.21968	0.014535	-23.572	0.15079	464.24	464.72
91.86867	-186.11	0.2231	0.014763	-23.578	0.14654	468.99	469.51
92.86867	-186.53	0.22564	0.014924	-23.647	0.14762	474.03	474.29
93.86866	-186.34	0.22767	0.015068	-23.627	0.14755	479.01	479.08
94.86866	-186.5	0.23021	0.015233	-23.631	0.14678	484.3	483.87
95.86866	-186.78	0.23198	0.015351	-23.689	0.14962	489.1	488.65
96.86866	-186.24	0.23379	0.015471	-23.636	0.14916	493.81	493.44
97.8318	-186.84	0.23533	0.015569	-23.706	0.14616	498.37	498.05
98.8318	-186.89	0.23728	0.015696	-23.711	0.14945	502.7	502.83
99.8318	-186.77	0.24028	0.015893	-23.7	0.15078	507.23	507.62
100.8318	-186.97	0.24303	0.016071	-23.735	0.15095	511.89	512.4
101.8318	-187.03	0.24478	0.016188	-23.739	0.14965	516.92	517.19
102.83179	-187.35	0.24701	0.016337	-23.784	0.15048	521.91	521.98
103.83179	-187.2	0.24883	0.016455	-23.766	0.14938	526.9	526.76
104.83179	-187.85	0.25031	0.016554	-23.846	0.14994	531.89	531.55
105.83179	-187.64	0.25189	0.016653	-23.827	0.15162	536.22	536.33
106.83179	-187.71	0.25388	0.016779	-23.841	0.15224	541.07	541.12
107.83179	-187.9	0.25653	0.016956	-23.864	0.15078	545.41	545.9
108.83179	-188.17	0.25846	0.017087	-23.888	0.15138	550	550.69
109.83179	-188.09	0.26053	0.017221	-23.891	0.1491	554.82	555.48
110.83179	-187.89	0.26267	0.017359	-23.89	0.1512	559.89	560.26
111.83179	-188.02	0.26469	0.017492	-23.881	0.14973	564.89	565.05
112.83179	-188.56	0.26597	0.017581	-23.956	0.15202	570.01	569.83
113.83178	-188.47	0.26723	0.017661	-23.949	0.15322	574.82	574.62
114.83178	-188.62	0.26887	0.017761	-23.971	0.15605	579.44	579.4
115.83178	-188.78	0.27051	0.017876	-24	0.15321	584.09	584.19
116.83178	-188.53	0.27174	0.017954	-23.978	0.15178	588.49	588.98
117.83178	-188.7	0.27419	0.018113	-23.99	0.15123	593.19	593.76
118.83178	-188.57	0.27617	0.018245	-23.985	0.15171	598.04	598.55
119.83178	-188.66	0.27703	0.018305	-23.998	0.15124	602.84	603.33
120.83178	-189.28	0.27814	0.01837	-24.075	0.15089	607.8	608.12
121.83178	-189.36	0.2799	0.018488	-24.076	0.15044	612.45	612.9
122.83178	-189.43	0.28097	0.01856	-24.086	0.15071	617.51	617.69
123.83177	-189.93	0.282	0.018623	-24.152	0.14895	622.43	622.48
124.83177	-189.79	0.28372	0.018743	-24.143	0.14949	626.93	627.26
125.83177	-189.35	0.28483	0.018812	-24.082	0.15212	631.89	632.05
126.83177	-190.03	0.2855	0.018857	-24.19	0.15361	636.6	636.83
127.83177	-189.83	0.2878	0.019009	-24.153	0.15547	641.4	641.62
128.83177	-189.74	0.28886	0.01908	-24.146	0.15495	646.2	646.4
129.83177	-190.23	0.29013	0.019159	-24.211	0.15369	650.81	651.19
130.83177	-190.06	0.29181	0.019269	-24.207	0.15414	655.6	655.97
131.83177	-190.29	0.29295	0.019346	-24.23	0.1529	660.57	660.76
132.83177	-190.07	0.29399	0.019411	-24.2	0.15355	665.51	665.55
133.83177	-190.83	0.29499	0.019472	-24.296	0.15172	670.36	670.33
134.83176	-190.46	0.29529	0.019499	-24.247	0.15119	675.24	675.12
135.83176	-190.78	0.29535	0.0195	-24.293	0.15102	679.94	679.9
136.83176	-191.95	0.29568	0.019519	-24.439	0.14871	684.48	684.69
137.83176	-191.21	0.29627	0.019557	-24.355	0.15267	689.14	689.48
138.8101	-191.32	0.29697	0.019606	-24.356	0.15113	693.9	694.16
139.8101	-191.29	0.29689	0.019599	-24.348	0.1514	698.52	698.94
140.8101	-89.23	0.31708	0.020917	-11.378	0.15263	703.04	703.9
141.8101	-89.647	0.32146	0.021207	-11.442	0.15116	707.53	708.9
142.8101	-89.586	0.32442	0.021402	-11.443	0.15081	712.17	713.9
143.81009	-89.592	0.32574	0.021483	-11.42	0.14948	717.13	718.9
144.81009	-90.065	0.32665	0.021542	-11.489	0.15343	722.25	723.9
145.81009	-91.344	0.3268	0.021555	-11.648	0.14916	727.67	728.9
146.81009	-90.231	0.32764	0.02161	-11.522	0.15096	732.85	733.9
147.81009	-89.178	0.3267	0.021551	-11.379	0.15135	737.69	738.9
148.81009	-84.482	0.32742	0.021597	-10.778	0.15077	742.62	743.9
149.81009	-79.092	0.32681	0.02155	-10.087	0.15054	746.92	748.9
150.81009	-81.065	0.32725	0.021586	-10.327	0.15075	749.78	753.9
151.81009	-90.447	0.32849	0.021665	-11.553	0.15095	750.32	758.9
152.81009	-90.25	0.33727	0.022237	-11.519	0.1547	749.77	763.9
153.81009	-89.614	0.35259	0.023235	-11.445	0.15254	751.47	768.9
154.81008	-89.434	0.36953	0.024337	-11.455	0.15292	758.4	773.9
155.81008	-87.858	0.37845	0.02492	-11.267	0.1501	783.07	778.9
156.81008	-59.37	0.3745	0.024658	-7.6034	0.155	814.75	783.9
157.81008	-52.021	0.34763	0.022911	-6.651	0.15111	829.61	788.9
158.81008	-50.197	0.33486	0.022076	-6.4148	0.15041	833.63	793.9
159.81008	-49.521	0.32431	0.021391	-6.3142	0.1498	831.1	798.9
160.81008	-49.412	0.31549	0.020811	-6.3077	0.15098	825.22	803.9
161.81008	-49.234	0.3074	0.020285	-6.2659	0.14881	817.73	808.9
162.81008	-49.883	0.30231	0.019949	-6.354	0.15153	810.12	813.9
163.81008	-70.966	0.30539	0.020152	-9.0347	0.15253	806.78	818.9
164.81007	-83.503	0.31354	0.020683	-10.664	0.15266	809.55	823.9
165.81007	-87.064	0.32583	0.02149	-11.103	0.15233	817.58	828.9
166.81007	-89.072	0.335	0.022087	-11.368	0.15331	828.64	833.9
167.81007	-89.394	0.34064	0.022454	-11.402	0.1502	840.12	838.9
168.81007	-84.826	0.34096	0.022477	-10.824	0.14927	848.72	843.9
169.81007	-74.16	0.34048	0.022451	-9.4618	0.14991	853.98	848.9
170.81007	-70.266	0.33977	0.022404	-8.9704	0.15144	856.53	853.9
171.81007	-78.129	0.3399	0.022404	-9.9824	0.1475	858.91	858.9
172.81007	-90.435	0.3412	0.022498	-11.541	0.14948	861.91	863.9
173.81007	-90.677	0.34555	0.022782	-11.579	0.14923	866.4	868.9
174.81007	-90.788	0.35002	0.023072	-11.599	0.1484	872.37	873.9
175.81006	-90.887	0.35359	0.0233	-11.616	0.15265	878.24	878.9
176.81006	-90.822	0.35523	0.023409	-11.591	0.15101	884.26	883.9
177.81006	-91.226	0.35683	0.023511	-11.679	0.15493	889.25	888.9
178.81006	-90.939	0.35876	0.023637	-11.627	0.15116	894.48	893.9
179.7821	-91.704	0.35963	0.023694	-11.729	0.14962	898.75	898.76
180.7821	-91.853	0.36247	0.023874	-11.751	0.14951	903.25	903.76
181.7821	-91.21	0.36377	0.023969	-11.668	0.15067	908.22	908.76
182.7821	-91.929	0.36692	0.024169	-11.758	0.1515	913.3	913.76
183.762	-91.86	0.36925	0.024315	-11.76	0.15001	918.53	918.65
184.762	-91.812	0.37073	0.024415	-11.749	0.14924	923.43	923.65
185.762	-92.336	0.37179	0.024487	-11.817	0.14873	928.58	928.65
186.762	-92.168	0.37343	0.02459	-11.799	0.14903	933.57	933.65
187.762	-92.365	0.37479	0.024678	-11.808	0.15501	938.55	938.65
188.762	-92.821	0.37506	0.02469	-11.876	0.15366	943.69	943.65
189.76199	-92.785	0.37633	0.024779	-11.891	0.15163	948.53	948.65
190.76199	-92.999	0.3764	0.024783	-11.904	0.15153	953.4	953.65
191.76199	-93.571	0.37727	0.024838	-11.973	0.15377	958.3	958.65
192.76199	-93.668	0.37824	0.024906	-11.95	0.14996	963.14	963.65
193.76199	-93.529	0.37813	0.024898	-11.971	0.15267	968.27	968.65
194.76199	-93.692	0.37869	0.024936	-11.989	0.15287	973.22	973.65
195.76199	-94.061	0.37789	0.02489	-12.039	0.14982	978.47	978.65
196.76199	-93.69	0.37747	0.024852	-11.989	0.15275	983.28	983.65
197.76199	-92.941	0.37831	0.024905	-11.887	0.14795	988.53	988.65
198.76199	-92.851	0.37843	0.024923	-11.868	0.15145	993.35	993.65
199.76198	-92.579	0.37837	0.024918	-11.847	0.15514	998.21	998.65
200.76198	-92.376	0.3783	0.024909	-11.821	0.15457	1003.1	1003.7
201.76198	-92.836	0.3781	0.0249	-11.859	0.15484	1008.5	1008.7
202.76198	-91.934	0.37832	0.02491	-11.779	0.15348	1013.3	1013.7
203.76198	-91.543	0.37811	0.024893	-11.73	0.15259	1018.5	1018.7
204.76198	-90.755	0.37826	0.024904	-11.624	0.1534	1023.4	1023.7
205.76198	-89.029	0.37808	0.024893	-11.408	0.15173	1027.9	1028.7
206.76198	-90.53	0.37804	0.024886	-11.591	0.15139	1032.6	1033.7
207.76198	-90.719	0.37871	0.024936	-11.62	0.15383	1037.6	1038.7
208.76198	-90.753	0.3786	0.02493	-11.614	0.15128	1042.9	1043.7
209.76198	-90.314	0.3786	0.024923	-11.557	0.14999	1048.2	1048.7
210.76197	-89.297	0.37845	0.024921	-11.46	0.15134	1053.2	1053.7
211.76197	-89.175	0.37833	0.024914	-11.394	0.15587	1058.3	1058.7
212.76197	-89.357	0.37771	0.024871	-11.439	0.15743	1063.4	1063.7
213.76197	-88.632	0.37843	0.024908	-11.347	0.15309	1068.7	1068.7
214.76197	-87.939	0.3774	0.024847	-11.238	0.15541	1073.4	1073.7
215.76197	-88.108	0.37748	0.024855	-11.28	0.15463	1078.5	1078.7
216.76197	-87.521	0.37786	0.024877	-11.185	0.15356	1083.1	1083.7
217.76197	-87.082	0.378	0.024893	-11.165	0.15205	1088.2	1088.7
218.76197	-86.574	0.37782	0.024877	-11.074	0.15324	1093.4	1093.7
219.76197	-85.246	0.3775	0.024854	-10.919	0.15226	1098.5	1098.7
220.6859	-84.209	0.37814	0.024895	-10.782	0.15174	1103.4	1103.3
221.6859	-83.57	0.37815	0.024904	-10.674	0.15532	1108	1108.3
222.6859	-82.605	0.37774	0.024876	-10.57	0.15931	1113	1113.3
223.6859	-82.121	0.37747	0.024856	-10.501	0.15854	1117.9	1118.3
224.6859	-80.519	0.3774	0.02485	-10.303	0.15729	1123.2	1123.3
225.68589	-79.854	0.3777	0.02487	-10.194	0.15533	1128	1128.3
226.68589	-78.61	0.37667	0.024808	-10.064	0.15559	1133.1	1133.3
227.68589	-77.04	0.37643	0.024784	-9.8658	0.15634	1138.1	1138.3
228.68589	-76.297	0.37702	0.024826	-9.7616	0.15362	1143	1143.3
229.68589	-75.936	0.37608	0.024769	-9.7338	0.15779	1147.8	1148.3
230.68589	-74.929	0.37631	0.024778	-9.5846	0.15512	1152.9	1153.3
231.68589	-73.981	0.3758	0.024741	-9.467	0.15463	1157.9	1158.3
232.68589	-73.559	0.3758	0.024744	-9.4037	0.15439	1163.2	1163.3
233.68589	-72.248	0.3753	0.024714	-9.2425	0.15331	1168.1	1168.3
234.68589	-71.401	0.37441	0.024652	-9.144	0.15873	1172.9	1173.3
235.68589	-70.944	0.37428	0.024644	-9.0745	0.15954	1177.9	1178.3
236.68588	-69.893	0.37383	0.024613	-8.9476	0.15956	1183.2	1183.3
237.68588	-70.122	0.37325	0.02458	-8.9751	0.16	1188.1	1188.3
238.68588	-69.243	0.37243	0.024529	-8.8715	0.16184	1193.5	1193.3
239.68588	-68.358	0.37229	0.024517	-8.7436	0.16073	1198.6	1198.3
240.68588	-65.261	0.37085	0.024425	-8.3748	0.1571	1202.6	1200
241.68588	-61.111	0.36888	0.024297	-7.7994	0.15579	1203.7	1200
242.68588	-60.048	0.36471	0.024027	-7.6734	0.15791	1203.5	1200
243.68588	-59.533	0.36302	0.023915	-7.6185	0.15515	1202.6	1200
244.68588	-59.146	0.36038	0.023742	-7.5707	0.1562	1201.4	1200
245.68588	-58.341	0.35901	0.023659	-7.4542	0.16121	1200.8	1200
246.68587	-58.62	0.35845	0.023622	-7.4841	0.16145	1200.3	1200
247.68587	-58.251	0.35687	0.023516	-7.4493	0.15894	1200.6	1200
248.68587	-57.992	0.35673	0.023504	-7.4225	0.15662	1200.1	1200
249.68587	-57.868	0.35591	0.023449	-7.3972	0.15753	1200.1	1200
250.68587	-57.307	0.35566	0.023434	-7.3416	0.1606	1200.1	1200
251.68587	-56.995	0.35489	0.023389	-7.2755	0.15831	1200.3	1200
252.68587	-56.333	0.35362	0.023303	-7.1863	0.15986	1200.3	1200
253.68587	-56.564	0.3525	0.023233	-7.223	0.15794	1200.5	1200
254.68587	-56.593	0.35212	0.023205	-7.2387	0.16004	1200.3	1200
255.68587	-56.43	0.35168	0.023173	-7.2066	0.15769	1200.4	1200
256.68587	-55.962	0.35052	0.023098	-7.1532	0.15969	1200.2	1200
257.68586	-56.105	0.35046	0.023096	-7.1706	0.16068	1200.3	1200
258.68586	-55.795	0.34968	0.023043	-7.1385	0.15991	1200.1	1200
259.68586	-55.653	0.34814	0.022944	-7.1172	0.15872	1200.2	1200
260.68586	-54.654	0.34851	0.022969	-7.0044	0.15937	1200.1	1200
261.6544	-55.089	0.34773	0.022916	-7.0505	0.15922	1199.9	1200
262.6544	-55.306	0.34662	0.022845	-7.0686	0.15973	1200.2	1200
263.6544	-55.006	0.34588	0.0228	-7.0327	0.15983	1200.5	1200
264.6544	-54.612	0.34528	0.02276	-6.9761	0.16013	1200.2	1200
265.6544	-54.849	0.34485	0.022726	-7	0.16023	1200.1	1200
266.65439	-54.111	0.34478	0.022724	-6.9071	0.15931	1199.9	1200
267.65439	-54.916	0.34468	0.022721	-7.0115	0.16038	1200.2	1200
268.65439	-55.151	0.344	0.022679	-7.0285	0.15768	1200.2	1200
269.65439	-54.487	0.34359	0.022651	-6.9613	0.15874	1200.2	1200
270.65439	-54.618	0.34247	0.022581	-6.9781	0.15839	1200.1	1200
271.65439	-53.981	0.34154	0.022521	-6.8993	0.15781	1199.9	1200
272.65439	-54.044	0.34143	0.02251	-6.9114	0.15826	1199.8	1200
273.65439	-53.728	0.34158	0.022516	-6.8517	0.15876	1200.2	1200
274.65439	-53.013	0.3418	0.022529	-6.7717	0.15743	1200.2	1200
275.65439	-53.711	0.34115	0.022488	-6.8715	0.15747	1200	1200
276.65439	-53.09	0.34119	0.022494	-6.7846	0.15853	1200.2	1200
277.65438	-53.909	0.34005	0.022416	-6.8963	0.15842	1199.9	1200
278.65438	-52.938	0.33977	0.022401	-6.7656	0.15935	1200.2	1200
279.65438	-53.472	0.33951	0.02238	-6.8354	0.15786	1199.9	1200
280.65438	-52.747	0.33968	0.022391	-6.7337	0.15878	1199.9	1200
281.65438	-53.323	0.3384	0.02231	-6.84	0.15907	1199.8	1200
282.65438	-53.172	0.33799	0.022281	-6.7686	0.15982	1199.7	1200
283.65438	-53.102	0.33684	0.022207	-6.7873	0.15818	1199.6	1200
284.65438	-53.746	0.33628	0.022171	-6.8746	0.15937	1199.5	1200
285.65438	-53.484	0.33647	0.02218	-6.8373	0.15806	1199.9	1200
286.65438	-53.921	0.33665	0.022195	-6.8715	0.15894	1200	1200
287.65437	-52.835	0.33594	0.022153	-6.739	0.15941	1200	1200
288.65437	-52.04	0.33545	0.022119	-6.635	0.15781	1200	1200
289.65437	-52.252	0.33529	0.022109	-6.6451	0.15914	1199.9	1200
290.65437	-53.609	0.33548	0.022119	-6.8535	0.15796	1200	1200
291.65437	-52.982	0.33511	0.022099	-6.7716	0.15921	1200.1	1200
292.65437	-53.752	0.33433	0.022046	-6.8544	0.15804	1200	1200
293.65437	-52.961	0.33451	0.022058	-6.7672	0.15755	1200	1200
294.65437	-52.298	0.33419	0.02204	-6.6759	0.15688	1199.9	1200
295.65437	-51.717	0.3336	0.022002	-6.5979	0.15921	1200.1	1200
296.65437	-52.447	0.3339	0.022019	-6.6741	0.16019	1199.9	1200
297.65437	-52.4	0.33353	0.021997	-6.6913	0.15886	1199.7	1200
298.65436	-52.062	0.33358	0.021997	-6.6523	0.15923	1200.2	1200
299.65436	-51.615	0.33377	0.022003	-6.5997	0.15943	1199.8	1200
300.65436	-53.432	0.33275	0.021939	-6.8136	0.15801	1200	1200
301.65436	-53.154	0.33219	0.021904	-6.7876	0.15926	1200.1	1200
302.6435	-52.271	0.33143	0.021848	-6.6704	0.15828	1199.9	1200
303.592	-52.197	0.3313	0.021847	-6.6586	0.16012	1199.8	1200
304.592	-53.268	0.33165	0.021868	-6.7944	0.15716	1199.8	1200
305.592	-52.761	0.3308	0.021812	-6.7526	0.15809	1199.9	1200
306.592	-52.55	0.33115	0.021839	-6.7367	0.15741	1199.9	1200
307.592	-51.467	0.33063	0.021806	-6.591	0.15606	1200	1200
308.592	-51.369	0.33034	0.021784	-6.5739	0.1592	1200.1	1200
309.59199	-50.364	0.33109	0.02183	-6.4351	0.15958	1199.9	1200
310.59199	-50.807	0.33073	0.02181	-6.4774	0.16047	1200	1200
311.59199	-53.396	0.32961	0.021738	-6.7982	0.15788	1200.1	1200
312.59199	-52.972	0.32938	0.021723	-6.7472	0.15713	1200.5	1200
313.59199	-52.07	0.32872	0.021681	-6.6351	0.1575	1200.7	1200
314.59199	-50.884	0.32923	0.021715	-6.4722	0.15737	1200.4	1200
315.59199	-53.158	0.32818	0.021648	-6.7721	0.15902	1200.5	1200
316.59199	-52.028	0.32745	0.021603	-6.6222	0.15703	1200.4	1200
317.59199	-52.488	0.32758	0.021607	-6.6822	0.15778	1200.1	1200
318.59199	-52.666	0.32652	0.021536	-6.6912	0.15883	1200.3	1200
319.59198	-51.954	0.3264	0.021539	-6.6211	0.15552	1200	1200
320.59198	-51.871	0.32657	0.021542	-6.6043	0.15716	1200.2	1200
321.59198	-50.845	0.32687	0.021557	-6.4751	0.15678	1200.2	1200
322.59198	-50.202	0.32658	0.021545	-6.4069	0.16044	1200	1200
323.59198	-52.346	0.32577	0.021488	-6.7042	0.15777	1200	1200
324.59198	-51.721	0.32549	0.021469	-6.6269	0.15903	1200	1200
325.59198	-51.753	0.3256	0.021476	-6.6134	0.15784	1200.1	1200
326.59198	-51.928	0.32573	0.021485	-6.6232	0.15726	1199.9	1200
327.59198	-51.147	0.32549	0.021463	-6.528	0.15759	1200	1200
328.59198	-51.371	0.32534	0.021459	-6.5546	0.15726	1200	1200
329.59197	-50.775	0.32501	0.02143	-6.4875	0.15808	1200.1	1200
330.59197	-52.115	0.32413	0.021378	-6.6491	0.1568	1200	1200
331.59197	-51.963	0.32363	0.021348	-6.6118	0.15857	1200	1200
332.59197	-52.06	0.32403	0.021374	-6.6432	0.1588	1200.1	1200
333.59197	-51.342	0.32411	0.021375	-6.5471	0.15995	1199.9	1200
334.59197	-50.294	0.32411	0.021379	-6.4092	0.1572	1200.3	1200
335.59197	-52.087	0.32319	0.021314	-6.6363	0.15784	1199.8	1200
336.59197	-51.783	0.32298	0.021307	-6.6037	0.15655	1200	1200
337.59197	-51.325	0.32242	0.021266	-6.5516	0.15728	1200	1200
338.59197	-51.268	0.32223	0.021257	-6.5334	0.15736	1199.9	1200
339.59197	-52.477	0.32255	0.021279	-6.6706	0.15552	1199.8	1200
340.59196	-51.201	0.32259	0.021282	-6.5226	0.15605	1200.1	1200
341.59196	-50.783	0.32187	0.021234	-6.4795	0.15651	1200.2	1200
342.59196	-50.187	0.32177	0.021231	-6.4164	0.15718	1200	1200
343.502	-50.031	0.32207	0.021251	-6.3977	0.15708	1200.1	1200
344.502	-52.131	0.32104	0.021178	-6.6447	0.1583	1199.9	1200
345.502	-52.871	0.32101	0.021177	-6.7291	0.15571	1199.8	1200
346.502	-51.453	0.321	0.021182	-6.5444	0.15686	1200	1200
347.502	-51.419	0.32084	0.021165	-6.5714	0.15589	1200.1	1200
348.50199	-50.828	0.32049	0.02114	-6.4854	0.15679	1200.1	1200
349.50199	-51.517	0.32035	0.021133	-6.5573	0.15657	1200	1200
350.50199	-50.467	0.32067	0.021153	-6.4315	0.1576	1200	1200
351.50199	-49.838	0.32102	0.021178	-6.3577	0.15837	1200.2	1200
352.50199	-51.449	0.3202	0.021119	-6.5608	0.15833	1199.9	1200
353.50199	-52.303	0.31855	0.021014	-6.6669	0.15844	1199.7	1200
354.50199	-53.001	0.31826	0.020993	-6.7597	0.15758	1199.5	1200
355.50199	-52.34	0.31795	0.020977	-6.672	0.15743	1199.7	1200
356.50199	-51.483	0.31827	0.020995	-6.5679	0.1575	1199.7	1200
357.50199	-51.243	0.31832	0.020998	-6.5334	0.16028	1199.6	1200
358.50199	-50.885	0.3185	0.021009	-6.4944	0.15895	1200	1200
359.50198	-50.979	0.31796	0.020975	-6.486	0.15514	1199.8	1200
360.50198	-51.287	0.31809	0.020987	-6.525	0.15815	1199.8	1200
361.50198	-50.037	0.31836	0.021003	-6.3867	0.15909	1200.2	1200
362.50198	-49.394	0.31806	0.020988	-6.2972	0.15644	1200.2	1200
363.50198	-52.137	0.31699	0.020918	-6.6547	0.15893	1200.1	1200
364.50198	-52.876	0.31646	0.020886	-6.757	0.15922	1200	1200
365.50198	-51.183	0.31644	0.020884	-6.5347	0.15688	1200.2	1200
366.50198	-50.722	0.3167	0.020896	-6.471	0.15925	1200.1	1200
367.50198	-50.465	0.31583	0.020846	-6.4416	0.15813	1200	1200
368.50198	-49.41	0.31644	0.020881	-6.328	0.15797	1200.1	1200
369.50197	-52.427	0.31541	0.020815	-6.697	0.15774	1199.8	1200
370.50197	-51.027	0.3151	0.020788	-6.5051	0.15875	1200	1200
371.50197	-50.804	0.31403	0.020719	-6.4821	0.15909	1199.8	1200
372.50197	-49.954	0.31437	0.020741	-6.3625	0.15936	1200.1	1200
373.50197	-50.005	0.3142	0.020727	-6.3732	0.16059	1199.7	1200
374.50197	-49.701	0.31397	0.020714	-6.3338	0.15925	1200	1200
375.50197	-49.622	0.31367	0.020695	-6.3279	0.1594	1200.1	1200
376.50197	-51.414	0.31304	0.020657	-6.5527	0.15889	1200.2	1200
377.50197	-50.658	0.31248	0.02062	-6.4521	0.15836	1199.9	1200
378.50197	-50.61	0.31152	0.020555	-6.4489	0.16034	1200.2	1200
379.50197	-50.521	0.31215	0.020594	-6.4406	0.1571	1200.3	1200
380.50196	-50.548	0.31185	0.020573	-6.4422	0.15949	1200.3	1200
381.50196	-49.543	0.31218	0.020593	-6.3203	0.16052	1200.3	1200
382.50196	-49.144	0.31147	0.020549	-6.262	0.15949	1200.2	1200
383.50196	-49.282	0.31136	0.02054	-6.293	0.15962	1200	1200
384.4858	-52.54	0.3104	0.020482	-6.6902	0.15909	1200.1	1200
385.4426	-52.271	0.30999	0.020463	-6.6882	0.15849	1200.3	1200
386.4426	-49.987	0.30973	0.020442	-6.389	0.15932	1200.5	1200
387.4426	-49.531	0.30926	0.020418	-6.3091	0.1576	1200.5	1200
388.4426	-52.352	0.30844	0.020363	-6.6523	0.15841	1200.2	1200
389.4426	-52.428	0.30784	0.020326	-6.6696	0.15923	1200	1200
390.4426	-51.885	0.30806	0.020336	-6.6035	0.15928	1199.8	1200
391.44259	-51.348	0.30744	0.02029	-6.5369	0.16103	1200	1200
392.44259	-50.614	0.30783	0.02032	-6.4365	0.1607	1200.2	1200
393.44259	-50.136	0.3073	0.020283	-6.3886	0.15943	1200.1	1200
394.44259	-51.765	0.30573	0.020182	-6.5953	0.15996	1199.9	1200
395.44259	-51.837	0.30556	0.020165	-6.5998	0.15947	1200.1	1200
396.44259	-51.106	0.3054	0.020152	-6.5115	0.16046	1199.8	1200
397.44259	-50.397	0.30546	0.020159	-6.4303	0.1578	1200.1	1200
398.44259	-50.264	0.30586	0.020183	-6.403	0.15933	1200.3	1200
399.44259	-50.724	0.30559	0.02016	-6.4644	0.16016	1200.1	1200
400.44259	-53.057	0.30476	0.02011	-6.7666	0.16053	1200.3	1200
401.44258	-51.793	0.30461	0.0201	-6.5882	0.15724	1200.1	1200
402.44258	-51.54	0.3042	0.020081	-6.5558	0.15901	1200	1200
403.44258	-50.068	0.30408	0.02007	-6.4	0.15913	1200.1	1200
404.44258	-50.834	0.30333	0.020021	-6.4943	0.15664	1200	1200
405.44258	-51.458	0.30322	0.020017	-6.5261	0.159	1200.1	1200
406.44258	-51.603	0.30232	0.019954	-6.5527	0.15959	1200.3	1200
407.44258	-52.705	0.3019	0.019924	-6.713	0.15885	1199.9	1200
408.44258	-51.292	0.30193	0.019925	-6.5357	0.15864	1200.1	1200
409.44258	-52.047	0.30152	0.019899	-6.6223	0.15817	1199.9	1200
410.44258	-51.025	0.30195	0.019934	-6.5274	0.15947	1200.3	1200
411.44257	-50.061	0.30176	0.019923	-6.3605	0.16112	1200.1	1200
412.44257	-50.526	0.30108	0.019878	-6.4389	0.15987	1200.2	1200
413.44257	-52.228	0.30094	0.019862	-6.651	0.15602	1200.1	1200
414.44257	-51.321	0.30069	0.01985	-6.5425	0.15922	1200.1	1200
415.44257	-50.599	0.3006	0.019848	-6.4355	0.15849	1200	1200
416.44257	-50.227	0.30066	0.019849	-6.4067	0.15895	1199.9	1200
417.44257	-50.881	0.30023	0.019824	-6.4819	0.15811	1199.8	1200
418.44257	-50.485	0.30048	0.019838	-6.4229	0.16219	1200.4	1200
419.44257	-50.406	0.2997	0.019788	-6.4003	0.16124	1200	1200
420.44257	-51.216	0.2992	0.019754	-6.5135	0.15779	1199.7	1197.9
421.44257	-52.434	0.29181	0.019275	-6.6694	0.15734	1195.9	1192.9
422.44256	-52.917	0.28446	0.01879	-6.723	0.15839	1190.9	1187.9
423.44256	-53.171	0.27819	0.018377	-6.7581	0.16137	1184.8	1182.9
424.44256	-53.48	0.27271	0.01801	-6.7961	0.16098	1179.4	1177.9
425.3759	-53.671	0.26824	0.017723	-6.8108	0.15953	1174.1	1173.3
426.3759	-53.743	0.26279	0.017365	-6.8125	0.15907	1169.2	1168.3
427.3759	-54.063	0.25686	0.01698	-6.8758	0.15882	1163.8	1163.3
428.3759	-53.843	0.25264	0.016703	-6.8396	0.15842	1158.7	1158.3
429.3759	-53.905	0.24713	0.016341	-6.8386	0.15846	1153.6	1153.3
430.3759	-54.572	0.24237	0.016026	-6.9096	0.15812	1148.5	1148.3
431.37589	-54.565	0.23695	0.015675	-6.9136	0.15764	1143.3	1143.3
432.37589	-54.495	0.23136	0.015307	-6.9003	0.15826	1138.2	1138.3
433.37589	-54.131	0.22711	0.015031	-6.8517	0.15881	1133.5	1133.3
434.37589	-54.224	0.22124	0.014648	-6.8645	0.15919	1128.5	1128.3
435.37589	-54.088	0.21653	0.014339	-6.8636	0.1576	1123.4	1123.3
436.37589	-54.669	0.21198	0.014038	-6.9291	0.15873	1118.3	1118.3
437.37589	-54.924	0.20742	0.013737	-6.9547	0.15787	1113.5	1113.3
438.37589	-54.902	0.20269	0.013429	-6.9535	0.15936	1108.5	1108.3
439.37589	-54.641	0.19776	0.013096	-6.9098	0.15723	1103.4	1103.3
440.37589	-54.892	0.19267	0.012762	-6.9371	0.15557	1098.4	1098.3
441.37588	-54.964	0.18793	0.012452	-6.9617	0.15635	1093.3	1093.3
442.37588	-55.147	0.18338	0.012156	-6.9597	0.15632	1088.2	1088.3
443.37588	-55.066	0.17881	0.011852	-6.9571	0.15759	1083.3	1083.3
444.37588	-55.024	0.17474	0.011581	-6.9495	0.15781	1078.2	1078.3
445.37588	-55.037	0.17059	0.011312	-6.959	0.15578	1073.3	1073.3
446.37588	-55.143	0.16584	0.010993	-6.965	0.1551	1068.4	1068.3
447.37588	-55.307	0.16143	0.010708	-6.9908	0.15654	1063.3	1063.3
448.37588	-55.004	0.15756	0.010454	-6.9436	0.15645	1058.3	1058.3
449.37588	-55.175	0.1533	0.010172	-6.9593	0.15998	1053.3	1053.3
450.37588	-54.953	0.14869	0.0098616	-6.9397	0.15676	1048.3	1048.3
451.37587	-55.259	0.14406	0.0095527	-6.9702	0.15723	1043.5	1043.3
452.37587	-55.62	0.13943	0.0092526	-7.012	0.15558	1038.3	1038.3
453.37587	-55.174	0.13567	0.0090071	-6.9629	0.15644	1033.4	1033.3
454.37587	-55.281	0.13103	0.0086995	-6.9684	0.15498	1028.4	1028.3
455.37587	-55.325	0.12667	0.0084081	-6.9602	0.15701	1023.5	1023.3
456.37587	-55.303	0.12178	0.0080811	-6.9627	0.15568	1018.4	1018.3
457.37587	-55.719	0.11718	0.0077839	-7.0223	0.1559	1013.2	1013.3
458.37587	-55.343	0.11271	0.0074915	-6.9558	0.15431	1008.4	1008.3
459.37587	-55.618	0.10852	0.0072128	-6.9798	0.15647	1003.3	1003.3
460.37587	-56.05	-0.00075267	-4.94E-05	-7.0059	0.1545	998.61	1000
461.065	-60.569	-0.0011666	-9.77E-05	-7.5581	0.13475	997.32	986.54
461.115	-57.931	-0.0022762	-0.00013745	-7.2075	-0.39231	997.1	938.53
461.165	-57.492	-0.0034942	-0.00024131	-6.9871	-0.90929	996.58	890.52
461.215	-53.456	-0.0049963	-0.00033001	-6.6734	-1.4627	996.26	842.5
461.265	-66.697	-0.0068431	-0.00045645	-8.2507	-1.9919	995.59	794.49
461.31501	-575.34	-0.43151	-0.029159	-69.606	-2.5199	995.29	746.48
461.36501	-722.56	-0.92777	-0.063791	-84.573	-3.0481	995.62	698.46
461.41501	-843.67	-1.4377	-0.10073	-95.359	-3.5854	995.9	650.45
461.46501	-953.43	-1.9512	-0.13927	-103.74	-4.1137	995.87	602.44
461.51501	-1065.5	-2.4726	-0.1801	-111.3	-4.6547	996.13	554.42
461.56501	-1164.4	-2.9765	-0.22113	-116.52	-5.1779	996.93	506.41
461.61501	-1245.1	-3.4873	-0.26451	-119.12	-5.7134	997.22	458.4
461.66501	-1323.9	-3.9931	-0.30946	-121.07	-6.2463	997.87	410.38
461.71502	-1370.2	-4.5057	-0.35715	-119.67	-6.7839	997.85	362.37
461.76502	-1463.5	-5.0099	-0.40637	-121.81	-7.3143	998.29	314.36
461.81502	-1545.4	-5.5108	-0.45781	-122.26	-7.8386	998.5	266.34
461.86502	-1669	-6.0271	-0.51378	-124.81	-8.3795	998.72	218.33
461.91502	-1797.7	-6.5379	-0.57235	-126.61	-8.9132	999.09	170.31
461.96502	-1929.4	-7.0351	-0.63292	-127.72	-9.4366	999.23	122.3
462.01502	-2107.9	-7.5395	-0.69838	-130.74	-9.9728	999.45	74.288
462.06502	-2351.6	-8.0314	-0.7665	-136.37	-10.501	999.47	26.275
462.11502	-2326.1	-8.4275	-0.82516	-127.35	-10.912	999.89	3.99E-07
462.16503	-1924.7	-8.476	-0.83262	-104.57	-10.942	999.63	9.20E-21
462.21503	-1640.2	-8.4915	-0.83496	-88.902	-10.946	999.28	2.12E-34
462.26503	-1445.9	-8.497	-0.83579	-78.298	-10.943	998.71	0
462.31503	-1311.8	-8.5007	-0.83636	-70.982	-10.94	997.82	0
462.36503	-1219	-8.5044	-0.83693	-65.894	-10.941	997.05	0
462.41503	-1178.9	-8.5096	-0.83767	-63.691	-10.943	996.2	0
462.46503	-1103.1	-8.5118	-0.83809	-59.573	-10.941	995.75	0
462.51503	-1056.3	-8.5144	-0.83845	-57.022	-10.941	995.03	0
462.56503	-1025.7	-8.5176	-0.83894	-55.37	-10.943	993.68	0
462.9916	-816.73	-8.5202	-0.83936	-44.048	-10.935	984.35	0
463.9916	-564.11	-8.517	-0.83886	-30.446	-10.914	950.51	0
464.9916	-405.83	-8.5094	-0.8377	-21.929	-10.896	916.81	0
465.9916	-277.48	-8.4975	-0.83585	-15.026	-10.877	889.68	0
466.9916	-175.34	-8.4877	-0.83434	-9.5104	-10.858	868.13	0
467.99159	-121.64	-8.4803	-0.83322	-6.6093	-10.845	849.41	0
468.99159	-103.87	-8.4806	-0.83328	-5.6362	-10.843	831.97	0
469.99159	-94.59	-8.4825	-0.83356	-5.1275	-10.844	815.46	0
470.99159	-81.704	-8.4838	-0.83376	-4.4286	-10.843	799.73	0
471.99159	-77.013	-8.4859	-0.83408	-4.1739	-10.843	784.63	0
472.99159	-70.779	-8.487	-0.83426	-3.8334	-10.844	770.13	0
473.99159	-65.275	-8.489	-0.83456	-3.5421	-10.843	755.86	0
474.99159	-62.846	-8.4917	-0.83498	-3.408	-10.845	741.73	0
475.99159	-59.151	-8.4936	-0.83527	-3.205	-10.843	728.13	0
476.99159	-57.437	-8.496	-0.83563	-3.1085	-10.845	714.9	0
477.99159	-54.902	-8.4989	-0.83608	-2.9689	-10.843	702.31	0
478.99158	-53.921	-8.5	-0.83625	-2.9143	-10.844	689.69	0
479.99158	-52.352	-8.5015	-0.83649	-2.8343	-10.842	677.72	0
480.99158	-51.795	-8.5026	-0.83664	-2.8021	-10.845	665.96	0
481.99158	-49.922	-8.5029	-0.8367	-2.705	-10.845	654.29	0
482.99158	-48.294	-8.5028	-0.83667	-2.6128	-10.844	642.73	0
483.99158	-47.418	-8.5026	-0.83664	-2.5636	-10.844	632.17	0
484.99158	-46.769	-8.5026	-0.83664	-2.531	-10.843	621.13	0
485.99158	-46.354	-8.5027	-0.83666	-2.5048	-10.844	610.76	0
486.99158	-45.579	-8.5028	-0.83667	-2.4632	-10.843	600.79	0
487.99158	-45.051	-8.5027	-0.83665	-2.4397	-10.845	591.65	0
488.99157	-44.339	-8.5029	-0.8367	-2.3952	-10.843	583.48	0
489.99157	-44.749	-8.5029	-0.83669	-2.4163	-10.849	576.9	0
490.99157	-43.57	-8.5035	-0.83679	-2.3551	-10.845	571.88	0
491.99157	-43.001	-8.5037	-0.83682	-2.3247	-10.845	569.08	0
492.99157	-42.924	-8.5037	-0.83682	-2.3178	-10.845	570.6	0
493.99157	-42.582	-8.5037	-0.83683	-2.3063	-10.846	576.63	0
494.99157	-42.314	-8.5037	-0.83684	-2.2873	-10.844	584.96	0
495.99157	-42.058	-8.5036	-0.8368	-2.277	-10.848	589.79	0
496.99157	-41.516	-8.5036	-0.8368	-2.247	-10.847	588.27	0
497.99157	-41.045	-8.5033	-0.83677	-2.2186	-10.849	581.5	0
498.99156	-40.049	-8.5019	-0.83656	-2.167	-10.845	570.81	0
499.99156	-39.455	-8.5007	-0.83636	-2.1367	-10.848	558.87	0
500.99156	-38.729	-8.4999	-0.83625	-2.0962	-10.847	545.73	0
501.99156	-38.574	-8.4996	-0.83619	-2.0878	-10.845	532.69	0
502.99156	-38.164	-8.4991	-0.83612	-2.0694	-10.845	520.33	0
503.99156	-37.533	-8.4986	-0.83604	-2.0322	-10.847	508.29	0
504.99156	-37.266	-8.4985	-0.83602	-2.0181	-10.846	496.97	0
505.99156	-36.991	-8.4984	-0.83599	-2.0035	-10.847	486.37	0
506.99156	-36.76	-8.4984	-0.836	-1.9907	-10.846	476.06	0
507.99156	-36.236	-8.4982	-0.83596	-1.9567	-10.846	466.41	0
508.99156	-36.238	-8.4978	-0.8359	-1.9618	-10.848	457.13	0
509.99155	-35.902	-8.4974	-0.83583	-1.9408	-10.846	448.13	0
510.99155	-35.707	-8.4974	-0.83585	-1.9319	-10.845	439.47	0
511.99155	-35.385	-8.4977	-0.83587	-1.9166	-10.844	431.32	0
512.99155	-35.183	-8.4976	-0.83587	-1.9062	-10.846	423.4	0
513.99155	-34.942	-8.4975	-0.83585	-1.8945	-10.844	415.47	0
514.99155	-34.725	-8.4976	-0.83588	-1.8787	-10.848	408.08	0
515.99155	-34.601	-8.4975	-0.83587	-1.8744	-10.846	400.53	0
516.99155	-34.21	-8.4977	-0.83589	-1.8555	-10.845	393.55	0
517.99155	-34.166	-8.4978	-0.8359	-1.8481	-10.847	386.66	0
518.99155	-33.872	-8.4978	-0.8359	-1.838	-10.845	379.81	0
519.99154	-33.587	-8.4979	-0.83592	-1.8179	-10.845	373.41	0
520.99154	-33.431	-8.4978	-0.83592	-1.8092	-10.846	366.81	0
521.99154	-33.381	-8.4981	-0.83595	-1.8048	-10.846	360.52	0
522.99154	-33.173	-8.4979	-0.83593	-1.7947	-10.847	354.42	0
523.99154	-32.713	-8.4981	-0.83596	-1.7698	-10.844	348.4	0
524.99154	-32.497	-8.4981	-0.83598	-1.7604	-10.848	342.75	0
525.99154	-32.406	-8.4982	-0.83596	-1.7548	-10.846	337.05	0
526.99154	-32.146	-8.4984	-0.83601	-1.7398	-10.844	331.55	0
527.99154	-32.132	-8.4983	-0.83599	-1.7379	-10.846	326.11	0
528.99154	-31.756	-8.4984	-0.83601	-1.718	-10.847	321.01	0
529.99154	-31.824	-8.4984	-0.836	-1.7223	-10.845	315.77	0
530.99153	-31.476	-8.4985	-0.83601	-1.7037	-10.845	310.59	0
531.99153	-31.033	-8.4986	-0.83603	-1.68	-10.845	305.57	0
532.99153	-30.949	-8.4985	-0.83601	-1.6732	-10.847	300.56	0
533.99153	-30.769	-8.4985	-0.83602	-1.6639	-10.845	296.09	0
534.99153	-30.598	-8.4988	-0.83605	-1.6572	-10.846	291.4	0
535.99153	-30.51	-8.4987	-0.83604	-1.6522	-10.845	287.13	0
536.99153	-30.42	-8.4987	-0.83605	-1.6435	-10.848	282.63	0
537.99153	-30.091	-8.4988	-0.83606	-1.6368	-10.846	278.33	0
538.99153	-29.706	-8.4988	-0.83608	-1.6081	-10.845	274.03	0
539.99153	-29.838	-8.499	-0.8361	-1.6151	-10.845	270.05	0
540.99152	-29.596	-8.4996	-0.83618	-1.5994	-10.844	266.05	0
541.99152	-29.302	-8.4997	-0.8362	-1.585	-10.845	262.03	0
542.99152	-29.11	-8.4998	-0.83622	-1.5728	-10.844	258.17	0
543.99152	-28.978	-8.4999	-0.83624	-1.5726	-10.846	254.33	0
544.99152	-28.633	-8.5	-0.83625	-1.555	-10.844	250.56	0
545.99152	-28.164	-8.5001	-0.83626	-1.5245	-10.846	246.76	0
546.99152	-28.045	-8.5	-0.83625	-1.5215	-10.844	243.25	0
547.99152	-27.829	-8.5002	-0.83629	-1.5057	-10.844	239.63	0
548.99152	-27.686	-8.5001	-0.83626	-1.5005	-10.844	236	0
549.99152	-27.803	-8.5003	-0.8363	-1.5052	-10.843	232.38	0
550.99152	-27.891	-8.5004	-0.83632	-1.5106	-10.843	228.89	0
551.99151	-27.685	-8.5011	-0.83642	-1.4989	-10.845	225.39	0
552.99151	-27.182	-8.5015	-0.83649	-1.4675	-10.842	221.89	0
553.99151	-27.022	-8.5019	-0.83653	-1.464	-10.842	218.48	0
554.99151	-27.008	-8.5024	-0.83662	-1.4587	-10.843	215.35	0
555.99151	-26.851	-8.5027	-0.83667	-1.4525	-10.845	212.03	0
556.99151	-26.466	-8.5029	-0.83669	-1.4331	-10.846	208.92	0
557.99151	-26.378	-8.5029	-0.83667	-1.4324	-10.844	205.72	0
558.99151	-26.018	-8.5032	-0.83673	-1.4104	-10.843	202.7	0
559.99151	-26.091	-8.5033	-0.83675	-1.4067	-10.845	199.72	0
560.99151	-25.758	-8.5043	-0.83692	-1.3905	-10.844	196.85	0
561.9915	-25.643	-8.5046	-0.83695	-1.3882	-10.842	194.18	0
562.9915	-25.329	-8.5048	-0.83698	-1.374	-10.843	191.44	0
563.9915	-25.352	-8.505	-0.83703	-1.3714	-10.843	188.54	0
564.9915	-25.217	-8.505	-0.83701	-1.3631	-10.842	186.04	0
565.9915	-24.79	-8.5054	-0.83708	-1.3451	-10.842	183.31	0
566.9915	-24.662	-8.5055	-0.83711	-1.333	-10.841	180.78	0
567.9915	-24.497	-8.5058	-0.83714	-1.3229	-10.844	178.3	0
568.9915	-24.348	-8.5057	-0.83714	-1.3149	-10.842	175.88	0
569.9915	-23.979	-8.5061	-0.83718	-1.2982	-10.844	173.36	0
570.9915	-23.793	-8.5062	-0.8372	-1.284	-10.843	170.72	0
571.9915	-23.862	-8.5062	-0.83721	-1.2928	-10.841	168.36	0
572.99149	-23.64	-8.5064	-0.83724	-1.2825	-10.843	166.08	0
573.99149	-23.126	-8.5065	-0.83726	-1.249	-10.844	163.85	0
574.99149	-23.049	-8.5067	-0.83727	-1.2456	-10.844	161.53	0
575.99149	-22.892	-8.5067	-0.83728	-1.2361	-10.845	159.38	0
576.99149	-22.754	-8.5067	-0.83728	-1.2259	-10.842	157.41	0
577.99149	-22.787	-8.5068	-0.83728	-1.2308	-10.842	155.06	0
578.99149	-22.5	-8.5068	-0.8373	-1.2122	-10.843	153.15	0
579.99149	-22.43	-8.5069	-0.8373	-1.214	-10.84	150.99	0
580.99149	-21.997	-8.507	-0.83732	-1.1908	-10.843	148.98	0
581.99149	-22.013	-8.5077	-0.83743	-1.1858	-10.842	147.13	0
582.99148	-21.907	-8.5078	-0.83743	-1.1855	-10.841	145.19	0
583.99148	-21.692	-8.5079	-0.83746	-1.1731	-10.844	143.18	0
584.99148	-21.374	-8.508	-0.83749	-1.1578	-10.84	141.31	0
585.99148	-21.372	-8.5082	-0.8375	-1.1534	-10.841	139.61	0
586.99148	-21.083	-8.5083	-0.83753	-1.1417	-10.844	137.97	0
587.99148	-20.821	-8.5082	-0.83752	-1.125	-10.845	136.33	0
588.99148	-20.768	-8.5084	-0.83755	-1.118	-10.845	134.63	0
589.99148	-20.714	-8.5083	-0.83754	-1.1213	-10.844	132.86	0
590.99148	-20.434	-8.5085	-0.83755	-1.1079	-10.846	131.04	0
591.99148	-20.381	-8.5085	-0.83755	-1.1016	-10.844	129.48	0
592.99148	-20.321	-8.5085	-0.83755	-1.097	-10.843	128	0
593.99147	-20.011	-8.5087	-0.83759	-1.0819	-10.841	126.47	0
594.99147	-19.648	-8.5087	-0.83759	-1.0661	-10.842	124.95	0
595.99147	-19.708	-8.5089	-0.83763	-1.064	-10.842	123.42	0
596.99147	-19.683	-8.5089	-0.83762	-1.0641	-10.842	122.14	0
597.99147	-19.369	-8.5091	-0.83765	-1.05	-10.842	120.59	0
598.99147	-19.214	-8.509	-0.83765	-1.0412	-10.844	119.15	0
599.99147	-18.884	-8.509	-0.83763	-1.0233	-10.843	118.06	0
600.99147	-19.087	-8.509	-0.83764	-1.0313	-10.843	116.5	0
601.99147	-18.659	-8.5089	-0.83763	-1.0126	-10.844	115.29	0
602.99147	-18.387	-8.5091	-0.83764	-0.99034	-10.845	114.01	0
603.99146	-18.566	-8.5091	-0.83764	-1.0041	-10.844	112.68	0
604.99146	-18.461	-8.5092	-0.83766	-1.0034	-10.846	111.5	0
605.99146	-18.202	-8.5092	-0.83766	-0.98282	-10.843	110.21	0
606.99146	-17.981	-8.5096	-0.83773	-0.97293	-10.844	109.1	0
607.99146	-17.821	-8.5098	-0.83775	-0.9679	-10.843	107.93	0
608.99146	-17.646	-8.5095	-0.8377	-0.95251	-10.842	106.9	0
609.99146	-17.668	-8.5097	-0.83775	-0.95247	-10.843	105.76	0
610.99146	-17.747	-8.5097	-0.83773	-0.96484	-10.843	104.71	0
611.99146	-17.335	-8.5099	-0.83777	-0.93638	-10.844	103.64	0
612.99146	-17.062	-8.5098	-0.83777	-0.91919	-10.845	102.75	0
613.99146	-17.291	-8.5099	-0.83776	-0.93502	-10.844	101.37	0
614.99145	-16.701	-8.51	-0.83779	-0.9007	-10.844	100.36	0
615.99145	-16.468	-8.5099	-0.83778	-0.89083	-10.846	99.416	0
616.99145	-16.702	-8.5101	-0.8378	-0.90353	-10.844	98.333	0
617.99145	-16.567	-8.51	-0.83778	-0.89487	-10.847	97.451	0
618.99145	-16.366	-8.5101	-0.83781	-0.88521	-10.844	96.561	0
619.99145	-16.219	-8.5101	-0.83782	-0.87553	-10.844	95.552	0
620.99145	-16.243	-8.5103	-0.83784	-0.87966	-10.845	94.625	0
621.99145	-15.803	-8.5103	-0.83783	-0.85576	-10.845	93.537	0
622.99145	-15.818	-8.5103	-0.83785	-0.85106	-10.841	92.732	0
623.99145	-16.079	-8.5104	-0.83785	-0.86518	-10.844	91.925	0
624.99144	-15.775	-8.5105	-0.83785	-0.85129	-10.844	91.081	0
625.99144	-15.601	-8.5106	-0.83789	-0.8427	-10.844	90.361	0
626.99144	-15.685	-8.5105	-0.83786	-0.84765	-10.844	89.508	0
627.99144	-15.153	-8.5105	-0.83786	-0.81956	-10.842	88.58	0
628.99144	-14.516	-8.5104	-0.83785	-0.78398	-10.841	87.856	0
629.99144	-14.639	-8.5105	-0.83786	-0.79163	-10.846	87.112	0
630.99144	-14.502	-8.5103	-0.83783	-0.78865	-10.844	86.415	0
631.99144	-14.086	-8.5102	-0.83782	-0.7623	-10.845	85.769	0
632.99144	-14.083	-8.5102	-0.8378	-0.75863	-10.843	84.833	0
633.99144	-13.929	-8.51	-0.83778	-0.75414	-10.845	84.362	0
634.99144	-13.658	-8.5099	-0.83776	-0.74014	-10.843	83.52	0
635.99143	-13.467	-8.5098	-0.83776	-0.72953	-10.843	82.737	0
636.99143	-13.603	-8.5098	-0.83776	-0.73067	-10.846	82.076	0
637.99143	-13.104	-8.5098	-0.83776	-0.70605	-10.848	81.33	0
638.99143	-13.539	-8.5099	-0.83777	-0.73674	-10.845	80.843	0
639.99143	-13.256	-8.5098	-0.83775	-0.71818	-10.843	80.099	0
640.99143	-13.064	-8.5098	-0.83776	-0.71043	-10.846	79.426	0
641.99143	-12.926	-8.5098	-0.83776	-0.69274	-10.846	78.704	0
642.99143	-12.814	-8.5097	-0.83775	-0.69572	-10.845	78.156	0
643.99143	-12.615	-8.5097	-0.83775	-0.68245	-10.845	77.676	0
644.99143	-12.719	-8.5096	-0.83774	-0.68662	-10.844	76.925	0
645.99142	-12.459	-8.5096	-0.83774	-0.67614	-10.846	76.291	0
646.99142	-12.282	-8.5095	-0.83771	-0.66706	-10.846	75.811	0
647.99142	-12.297	-8.5096	-0.83773	-0.66666	-10.845	75.163	0
648.99142	-12.352	-8.5095	-0.8377	-0.66864	-10.848	74.717	0
649.99142	-11.995	-8.5095	-0.8377	-0.64686	-10.845	74.267	0
650.99142	-12.115	-8.5094	-0.83769	-0.65059	-10.847	73.574	0
651.99142	-11.929	-8.5094	-0.83769	-0.64339	-10.843	73.082	0
652.99142	-11.844	-8.5094	-0.83769	-0.6457	-10.843	72.551	0
653.99142	-11.559	-8.5093	-0.83768	-0.62402	-10.846	71.833	0
654.99142	-11.514	-8.5094	-0.83769	-0.62315	-10.845	71.418	0
655.99142	-11.602	-8.5092	-0.83765	-0.62648	-10.845	70.997	0
656.99141	-11.307	-8.5094	-0.83769	-0.60915	-10.847	70.573	0
657.99141	-11.264	-8.5092	-0.83766	-0.61188	-10.845	70.039	0
658.99141	-11.163	-8.5092	-0.83767	-0.6025	-10.847	69.496	0
659.99141	-10.971	-8.5091	-0.83765	-0.59946	-10.844	69.126	0
660.99141	-11.073	-8.5091	-0.83764	-0.60041	-10.848	68.649	0
661.99141	-10.838	-8.5091	-0.83766	-0.59169	-10.848	68.013	0
662.99141	-10.52	-8.509	-0.83763	-0.5717	-10.846	67.588	0
663.99141	-10.397	-8.509	-0.83764	-0.56459	-10.844	67.248	0
664.99141	-10.575	-8.509	-0.83763	-0.57611	-10.846	66.784	0
665.99141	-10.479	-8.509	-0.83763	-0.56778	-10.845	67.127	0
666.9914	-10.287	-8.5089	-0.83762	-0.55434	-10.847	67.779	0
667.9914	-10.552	-8.5089	-0.83761	-0.57006	-10.847	68.184	0
668.9914	-10.155	-8.5088	-0.83761	-0.55259	-10.848	68.529	0
669.9914	-10.14	-8.5088	-0.8376	-0.54622	-10.847	68.97	0
670.9914	-9.9283	-8.5087	-0.8376	-0.53397	-10.848	69.279	0
671.9914	-10.103	-8.5087	-0.83758	-0.54604	-10.848	69.96	0
672.9914	-10.087	-8.5087	-0.83757	-0.54323	-10.847	70.198	0
673.9914	-10.087	-8.5087	-0.83757	-0.54323	-10.847	70.198	0
674.9914	-10.087	-8.5087	-0.83757	-0.54323	-10.847	70.198	0
675.9914	-10.087	-8.5087	-0.83757	-0.54323	-10.847	70.198	0
676.9914	-10.087	-8.5087	-0.83757	-0.54323	-10.847	70.198	0
677.99139	-10.087	-8.5087	-0.83757	-0.54323	-10.847	70.198	0
678.99139	-10.087	-8.5087	-0.83757	-0.54323	-10.847	70.198	0
679.99139	-10.087	-8.5087	-0.83757	-0.54323	-10.847	70.198	0
680.99139	-10.087	-8.5087	-0.83757	-0.54323	-10.847	70.198	0
681.99139	-10.087	-8.5087	-0.83757	-0.54323	-10.847	70.198	0
682.99139	-10.087	-8.5087	-0.83757	-0.54323	-10.847	70.198	0
683.99139	-10.087	-8.5087	-0.83757	-0.54323	-10.847	70.198	0
684.99139	-10.087	-8.5087	-0.83757	-0.54323	-10.847	70.198	0
685.99139	-10.087	-8.5087	-0.83757	-0.54323	-10.847	70.198	0
686.99139	-10.087	-8.5087	-0.83757	-0.54323	-10.847	70.198	0
687.99138	-10.087	-8.5087	-0.83757	-0.54323	-10.847	70.198	0
688.99138	-10.087	-8.5087	-0.83757	-0.54323	-10.847	70.198	0
689.99138	-10.087	-8.5087	-0.83757	-0.54323	-10.847	70.198	0
690.99138	-10.087	-8.5087	-0.83757	-0.54323	-10.847	70.198	0
691.99138	-10.087	-8.5087	-0.83757	-0.54323	-10.847	70.198	0
692.99138	-10.087	-8.5087	-0.83757	-0.54323	-10.847	70.198	0
693.99138	-10.087	-8.5087	-0.83757	-0.54323	-10.847	70.198	0
694.99138	-10.087	-8.5087	-0.83757	-0.54323	-10.847	70.198	0
695.99138	-10.087	-8.5087	-0.83757	-0.54323	-10.847	70.198	0
696.99138	-10.087	-8.5087	-0.83757	-0.54323	-10.847	70.198	0
697.99138	-10.087	-8.5087	-0.83757	-0.54323	-10.847	70.198	0
698.99137	-10.087	-8.5087	-0.83757	-0.54323	-10.847	70.198	0
699.99137	-10.087	-8.5087	-0.83757	-0.54323	-10.847	70.198	0
700.99137	-10.087	-8.5087	-0.83757	-0.54323	-10.847	70.198	0
701.99137	-10.087	-8.5087	-0.83757	-0.54323	-10.847	70.198	0
702.99137	-10.087	-8.5087	-0.83757	-0.54323	-10.847	70.198	0
703.99137	-10.087	-8.5087	-0.83757	-0.54323	-10.847	70.198	0
704.99137	-10.087	-8.5087	-0.83757	-0.54323	-10.847	70.198	0
705.99137	-10.087	-8.5087	-0.83757	-0.54323	-10.847	70.198	0
706.99137	-10.087	-8.5087	-0.83757	-0.54323	-10.847	70.198	0
707.59137	-10.087	-8.5087	-0.83757	-0.54323	-10.847	70.198	0